
  0%|                                                                                                                | 0/4621 [00:00<?, ?it/s]
0.201316


























































































































































































































































































Epoch: 0/99 Phase: train Loss: 0.7013 (0.6752) Acc: 0.0050 (0.0071) Acc PER: 0.7295 (0.7377):   6%|â–Ž     | 281/4621 [10:58<2:50:56,  2.36s/it]Exception in thread Thread-5:
Traceback (most recent call last):
  File "/usr/lib/python3.6/threading.py", line 916, in _bootstrap_inner
    self.run()
  File "/usr/lib/python3.6/threading.py", line 864, in run
    self._target(*self._args, **self._kwargs)
  File "/root/virtualenvs/pytorch_1.4/lib/python3.6/site-packages/wandb/sdk/wandb_run.py", line 185, in check_network_status
    status_response = self._interface.communicate_network_status()
  File "/root/virtualenvs/pytorch_1.4/lib/python3.6/site-packages/wandb/sdk/interface/interface.py", line 749, in communicate_network_status
    resp = self._communicate(req, timeout=timeout, local=True)
  File "/root/virtualenvs/pytorch_1.4/lib/python3.6/site-packages/wandb/sdk/interface/interface.py", line 539, in _communicate
    return self._communicate_async(rec, local=local).get(timeout=timeout)
  File "/root/virtualenvs/pytorch_1.4/lib/python3.6/site-packages/wandb/sdk/interface/interface.py", line 544, in _communicate_async
    raise Exception("The wandb backend process has shutdown")
Exception: The wandb backend process has shutdown




