
  0%|                                                                                                                | 0/4621 [00:00<?, ?it/s]
0.133604



























































































































































































































































































































































































































































































































































































































































































































































































































































































































































































































































































































































































































































































































































































































































































































































Epoch: 0/99 Phase: train Loss: 0.3822 (0.3001) Acc: 0.0028 (0.0036) Acc PER: 0.8261 (0.8438):  75%|███▋ | 3456/4621 [1:28:38<29:52,  1.54s/it]
Traceback (most recent call last):
  File "/root/virtualenvs/pytorch_1.4/lib/python3.6/site-packages/torch/utils/data/dataloader.py", line 761, in _try_get_data
    data = self._data_queue.get(timeout=timeout)
  File "/usr/lib/python3.6/multiprocessing/queues.py", line 113, in get
    return _ForkingPickler.loads(res)
  File "/root/virtualenvs/pytorch_1.4/lib/python3.6/site-packages/torch/multiprocessing/reductions.py", line 294, in rebuild_storage_fd
    fd = df.detach()
  File "/usr/lib/python3.6/multiprocessing/resource_sharer.py", line 57, in detach
    with _resource_sharer.get_connection(self._id) as conn:
  File "/usr/lib/python3.6/multiprocessing/resource_sharer.py", line 87, in get_connection
    c = Client(address, authkey=process.current_process().authkey)
  File "/usr/lib/python3.6/multiprocessing/connection.py", line 493, in Client
    answer_challenge(c, authkey)
  File "/usr/lib/python3.6/multiprocessing/connection.py", line 732, in answer_challenge
    message = connection.recv_bytes(256)         # reject large message
  File "/usr/lib/python3.6/multiprocessing/connection.py", line 216, in recv_bytes
    buf = self._recv_bytes(maxlength)
  File "/usr/lib/python3.6/multiprocessing/connection.py", line 407, in _recv_bytes
    buf = self._recv(4)
  File "/usr/lib/python3.6/multiprocessing/connection.py", line 379, in _recv
    chunk = read(handle, remaining)
  File "/root/virtualenvs/pytorch_1.4/lib/python3.6/site-packages/torch/utils/data/_utils/signal_handling.py", line 66, in handler
    _error_if_any_worker_fails()
RuntimeError: DataLoader worker (pid 14008) is killed by signal: Killed.
During handling of the above exception, another exception occurred:
Traceback (most recent call last):
  File "train.py", line 314, in <module>
    wandb,
  File "train.py", line 79, in train
    for idx, sample in pbar:
  File "/root/virtualenvs/pytorch_1.4/lib/python3.6/site-packages/tqdm/std.py", line 1133, in __iter__
    for obj in iterable:
  File "/root/virtualenvs/pytorch_1.4/lib/python3.6/site-packages/torch/utils/data/dataloader.py", line 345, in __next__
    data = self._next_data()
  File "/root/virtualenvs/pytorch_1.4/lib/python3.6/site-packages/torch/utils/data/dataloader.py", line 841, in _next_data
    idx, data = self._get_data()
  File "/root/virtualenvs/pytorch_1.4/lib/python3.6/site-packages/torch/utils/data/dataloader.py", line 808, in _get_data
    success, data = self._try_get_data()
  File "/root/virtualenvs/pytorch_1.4/lib/python3.6/site-packages/torch/utils/data/dataloader.py", line 774, in _try_get_data
    raise RuntimeError('DataLoader worker (pid(s) {}) exited unexpectedly'.format(pids_str))
RuntimeError: DataLoader worker (pid(s) 14008) exited unexpectedly