0.287204
LR:  0.001












































































































































































































































































































































































































































































































































































































































































































































































Epoch: 0/99 Phase: train Loss: 0.2134 (0.1034) Acc: 0.0035 (0.0033) Acc PER: 0.9194 (0.9286):  48%|███▎   | 2206/4621 [44:41<48:55,  1.22s/it]
Traceback (most recent call last):
  File "/root/virtualenvs/pytorch_1.4/lib/python3.6/site-packages/torch/utils/data/dataloader.py", line 761, in _try_get_data
    data = self._data_queue.get(timeout=timeout)
  File "/usr/lib/python3.6/multiprocessing/queues.py", line 104, in get
    if not self._poll(timeout):
  File "/usr/lib/python3.6/multiprocessing/connection.py", line 257, in poll
    return self._poll(timeout)
  File "/usr/lib/python3.6/multiprocessing/connection.py", line 414, in _poll
    r = wait([self], timeout)
  File "/usr/lib/python3.6/multiprocessing/connection.py", line 911, in wait
    ready = selector.select(timeout)
  File "/usr/lib/python3.6/selectors.py", line 376, in select
    fd_event_list = self._poll.poll(timeout)
  File "/root/virtualenvs/pytorch_1.4/lib/python3.6/site-packages/torch/utils/data/_utils/signal_handling.py", line 66, in handler
    _error_if_any_worker_fails()
RuntimeError: DataLoader worker (pid 8736) is killed by signal: Killed.
During handling of the above exception, another exception occurred:
Traceback (most recent call last):
  File "train.py", line 314, in <module>
    wandb,
  File "train.py", line 79, in train
    for idx, sample in pbar:
  File "/root/virtualenvs/pytorch_1.4/lib/python3.6/site-packages/tqdm/std.py", line 1133, in __iter__
    for obj in iterable:
  File "/root/virtualenvs/pytorch_1.4/lib/python3.6/site-packages/torch/utils/data/dataloader.py", line 345, in __next__
    data = self._next_data()
  File "/root/virtualenvs/pytorch_1.4/lib/python3.6/site-packages/torch/utils/data/dataloader.py", line 841, in _next_data
    idx, data = self._get_data()
  File "/root/virtualenvs/pytorch_1.4/lib/python3.6/site-packages/torch/utils/data/dataloader.py", line 808, in _get_data
    success, data = self._try_get_data()
  File "/root/virtualenvs/pytorch_1.4/lib/python3.6/site-packages/torch/utils/data/dataloader.py", line 774, in _try_get_data
    raise RuntimeError('DataLoader worker (pid(s) {}) exited unexpectedly'.format(pids_str))
RuntimeError: DataLoader worker (pid(s) 8736) exited unexpectedly